Workbook

Sheet Lighting
A1: Invento | B1: E200 | C1: Column2 | D1: Column3 | E1: Column4 | F1: Total | H1: Project Name: | I1: HCMC Histology Lab | J1: Due Date: | K1: Dec. 11th
A2: A1 | B2: 48 | F2: =SUM(Lighting!$B2:$E2) -> 48
A3: A6 | B3: 14 | F3: =SUM(Lighting!$B3:$E3) -> 14
A4: B1 | B4: 4 | F4: =SUM(Lighting!$B4:$E4) -> 4
A5: B6 | B5: 25 | F5: =SUM(Lighting!$B5:$E5) -> 25
A6: D7 | B6: 1 | F6: =SUM(Lighting!$B6:$E6) -> 1
A7: E3 | B7: 4 | F7: =SUM(Lighting!$B7:$E7) -> 4
A8: E4 | B8: 3 | F8: =SUM(Lighting!$B8:$E8) -> 3
A9: L5 | B9: 3 | F9: =SUM(Lighting!$B9:$E9) -> 3
A10: U2 | B10: 2 | F10: =SUM(Lighting!$B10:$E10) -> 2
A11: U3 | B11: 6 | F11: 7
A12: U4 | B12: 3 | F12: 4
F13: =SUM(Lighting!$B13:$E13) -> 0
A14: Alternate 1 | F14: =SUM(Lighting!$B14:$E14) -> 0
A15: B6 | B15: 1 | F15: =SUM(Lighting!$B15:$E15) -> 1
A16: C4 | B16: 1 | F16: =SUM(Lighting!$B16:$E16) -> 1
A17: OS | B17: 1 | F17: =SUM(Lighting!$B17:$E17) -> 1
F18: =SUM(Lighting!$B18:$E18) -> 0
A19: Alternate 2 | F19: =SUM(Lighting!$B19:$E19) -> 0
A20: D1/Dimmer | B20: 1 | F20: =SUM(Lighting!$B20:$E20) -> 1
A21: D6 | B21: 4 | F21: =SUM(Lighting!$B21:$E21) -> 4
F22: =SUM(Lighting!$B22:$E22) -> 0
A23: CONTROLS | F23: =SUM(Lighting!$B23:$E23) -> 0
A24: COS1S | B24: 3 | F24: =SUM(Lighting!$B24:$E24) -> 3
A25: D1 | B25: 11 | F25: =SUM(Lighting!$B25:$E25) -> 11
A26: D1S | B26: 3 | F26: =SUM(Lighting!$B26:$E26) -> 3
A27: D3 | B27: 5 | F27: =SUM(Lighting!$B27:$E27) -> 5
A28: OS | B28: 2 | F28: =SUM(Lighting!$B28:$E28) -> 2
A29: PB4D | B29: 2 | F29: =SUM(Lighting!$B29:$E29) -> 2
A30: SWITCH | B30: 6 | F30: =SUM(Lighting!$B30:$E30) -> 6
F31: =SUM(Lighting!$B31:$E31) -> 0
F32: =SUM(Lighting!$B32:$E32) -> 0
F33: =SUM(Lighting!$B33:$E33) -> 0
F34: =SUM(Lighting!$B34:$E34) -> 0
F35: =SUM(Lighting!$B35:$E35) -> 0
F36: =SUM(Lighting!$B36:$E36) -> 0
F37: =SUM(Lighting!$B37:$E37) -> 0
F38: =SUM(Lighting!$B38:$E38) -> 0
F39: =SUM(Lighting!$B39:$E39) -> 0
F40: =SUM(Lighting!$B40:$E40) -> 0
...

Sheet Keynotes
A1: KeyNote/Page | B1: E200
A2: 1 | B2: 6
A3: 2 | B3: 1
A4: 3 | B4: 1
